Workbook

Sheet EV_Registrations
A1: State | B1: 2020 | C1: 2021 | D1: 2022 | E1: 2023 | F1: 2024 | G1: 2025 | H1: 2026
A2: Andhra Pradesh | B2: 1654 | C2: 9738 | D2: 29450 | E2: 29546
A3: Assam | B3: 8357 | C3: 15634 | D3: 40719 | E3: 56448
A4: Bihar | B4: 12447 | C4: 23082 | D4: 55751 | E4: 79469
A5: Delhi | B5: 12377 | C5: 25816 | D5: 62256 | E5: 64382
A6: Gujarat | B6: 1120 | C6: 9765 | D6: 68998 | E6: 83965
A9: EV SEGMENT SALES
A10: Financial year | B10: e-2w | C10: e-3W e-rickshaw/e-cart | D10: e-3W L5 | E10: e-trucks | F10: Total
A20: ev penetration | C20: EV 2W sales
C21: ────────────── × 100
C22: Total 2W sales
A25: State | B25: 2020 | C25: 2021 | D25: 2022 | E25: 2023_YTD | F25: Grand_Total
A26: Andaman & Nicobar Islands | B26: 36 | C26: 92 | D26: 23 | E26: 18 | F26: =SUM(B26:E26) -> 169
A27: Andhra Pradesh | B27: 1654 | C27: 9738 | D27: 29450 | E27: 29546 | F27: =SUM(B27:E27) -> 70388
A28: Arunachal Pradesh | B28: 5 | C28: 2 | D28: 2 | E28: 17 | F28: =SUM(B28:E28) -> 26
A29: Assam | B29: 8357 | C29: 15634 | D29: 40719 | E29: 56448 | F29: =SUM(B29:E29) -> 121158
A30: Bihar | B30: 12447 | C30: 23082 | D30: 55751 | E30: 79469 | F30: =SUM(B30:E30) -> 170749
A31: Chandigarh | B31: 369 | C31: 734 | D31: 2721 | E31: 5753 | F31: =SUM(B31:E31) -> 9577
A32: Chhattisgarh | B32: 1489 | C32: 4215 | D32: 22364 | E32: 35115 | F32: =SUM(B32:E32) -> 63183 | J32: because year didn't complete
A33: Delhi | B33: 12377 | C33: 25816 | D33: 62256 | E33: 64382 | F33: =SUM(B33:E33) -> 164831
A34: Goa | B34: 82 | C34: 1096 | D34: 5688 | E34: 8637 | F34: =SUM(B34:E34) -> 15503
A35: Gujarat | B35: 1120 | C35: 9765 | D35: 68998 | E35: 83965 | F35: =SUM(B35:E35) -> 163848
A36: Haryana | B36: 2982 | C36: 8660 | D36: 25864 | E36: 27465 | F36: =SUM(B36:E36) -> 64971
A37: Himachal Pradesh | B37: 181 | C37: 327 | D37: 1008 | E37: 1003 | F37: =SUM(B37:E37) -> 2519
A38: Jammu & Kashmir | B38: 74 | C38: 1146 | D38: 4689 | E38: 8823 | F38: =SUM(B38:E38) -> 14732
A39: Jharkhand | B39: 1516 | C39: 3741 | D39: 13682 | E39: 19096 | F39: =SUM(B39:E39) -> 38035
A40: Karnataka | B40: 9707 | C40: 33307 | D40: 95900 | E40: 141057 | F40: =SUM(B40:E40) -> 279971
A41: Kerala | B41: 1362 | C41: 8743 | D41: 39622 | E41: 69624 | F41: =SUM(B41:E41) -> 119351
A42: Ladakh | B42: 0 | C42: 6 | D42: 40 | E42: 28 | F42: =SUM(B42:E42) -> 74
A43: Madhya Pradesh | B43: 3358 | C43: 10427 | D43: 36804 | E43: 61678 | F43: =SUM(B43:E43) -> 112267
A44: Maharashtra | B44: 7134 | C44: 29914 | D44: 136051 | E44: 178488 | F44: =SUM(B44:E44) -> 351587
... A58: West Bengal | B58: 10079 | C58: 6408 | D58: 11150 | E58: 17699 | F58: =SUM(B58:E58) -> 45336
A59: Grand Total | B59: =SUM(B26:B58) -> 124681 | C59: =SUM(C26:C58) -> 331635 | D59: =SUM(D26:D58) -> 1025118 | E59: =SUM(E26:E58) -> 1395701 | F59: =SUM(F26:F58) -> 2877135

Sheet SIAM_Total_Sales
A1: Financial Year | B1: Passenger Vehicles | C1: Commercial Vehicles | D1: Three Wheelers | E1: Two Wheelers | F1: Total | G1: Source | H1: Data Type
A2: FY2020-21 | B2: 2711457 | C2: 568559 | D2: 219446 | E2: 15120783 | F2: =SUM(B2:E2) -> 18620245 | G2: SIAM – Automobile Domestic Sales Trends | H2: Domestic Sales
A3: FY2021-22 | B3: 3069523 | C3: 716566 | D3: 261385 | E3: 13570008 | F3: =SUM(B3:E3) -> 17617482 | G3: SIAM – Automobile Domestic Sales Trends | H3: Domestic Sales
A4: FY2022-23 | B4: 3890114 | C4: 962468 | D4: 488768 | E4: 15862771 | F4: =SUM(B4:E4) -> 21204121 | G4: SIAM – Automobile Domestic Sales Trends | H4: Domestic Sales
A5: FY2023-24 | B5: 4218750 | C5: 968770 | D5: 694801 | E5: 17974365 | F5: =SUM(B5:E5) -> 23856686 | G5: SIAM – Automobile Domestic Sales Trends | H5: Domestic Sales
A6: FY2024-25 | B6: 4301848 | C6: 958679 | D6: 741420 | E6: 19607332 | F6: =SUM(B6:E6) -> 25609279 | G6: SIAM – Automobile Domestic Sales Trends | H6: Domestic Sales
A7: FY2025-26 | B7: 4643439 | C7: 1079871 | D7: 836231 | E7: 21705974 | F7: =SUM(B7:E7) -> 28265515 | G7: SIAM – Automobile Domestic Sales Trends | H7: Domestic Sales

Sheet ev_segment_data
A1: Year | B1: Vehicle Segment | C1: Total Vehicles | D1: EV Vehicles | E1: EV Penetration | F1: Source | G1: Data Type
A2: 2020 | B2: Two Wheeler | C2: 14305129 | D2: 29113 | E2: =D2/C2 -> 0.0020351442 | F2: MHI / Vahan4 | G2: Registrations
B3: Three Wheeler | C3: 400893 | D3: 90385 | E3: =D3/C3 -> 0.22545916 | F3: MHI / Vahan4 | G3: Registrations
B4: Four Wheeler | C4: 2396428 | D4: 3207 | E4: =D4/C4 -> 0.0013382417 | F4: MHI / Vahan4 | G4: Registrations
B5: Goods Vehicles | C5: 503358 | D5: 15 | E5: =D5/C5 -> 2.9799864e-05 | F5: MHI / Vahan4 | G5: Registrations
B6: Public Service Vehicle | C6: 40328 | D6: 88 | E6: =D6/C6 -> 0.0021821067 | F6: MHI / Vahan4 | G6: Registrations
A7: 2021 | B7: Two Wheeler | C7: 13926217 | D7: 156243 | E7: =D7/C7 -> 0.011219343 | F7: MHI / Vahan4 | G7: Registrations
B8: Three Wheeler | C8: 390820 | D8: 158129 | E8: =D8/C8 -> 0.40460826 | F8: MHI / Vahan4 | G8: Registrations
B9: Four Wheeler | C9: 2945340 | D9: 12259 | E9: =D9/C9 -> 0.004162168 | F9: MHI / Vahan4 | G9: Registrations
B10: Goods Vehicles | C10: 602805 | D10: 1118 | E10: =D10/C10 -> 0.0018546628 | F10: MHI / Vahan4 | G10: Registrations
B11: Public Service Vehicle | C11: 15434 | D11: 1177 | E11: =D11/C11 -> 0.076260205 | F11: MHI / Vahan4 | G11: Registrations
A12: 2022 | B12: Two Wheeler | C12: 15592118 | D12: 631181 | E12: =D12/C12 -> 0.040480774 | F12: MHI / Vahan4 | G12: Registrations
B13: Three Wheeler | C13: 677034 | D13: 350247 | E13: =D13/C13 -> 0.51732557 | F13: MHI / Vahan4 | G13: Registrations
B14: Four Wheeler | C14: 3346973 | D14: 33205 | E14: =D14/C14 -> 0.0099209047 | F14: MHI / Vahan4 | G14: Registrations
B15: Goods Vehicles | C15: 804409 | D15: 653 | E15: =D15/C15 -> 0.0008117761 | F15: MHI / Vahan4 | G15: Registrations
B16: Public Service Vehicle | C16: 45448 | D16: 1972 | E16: =D16/C16 -> 0.043390248 | F16: MHI / Vahan4 | G16: Registrations
A17: 2023_YTD | B17: Two Wheeler | C17: 9276337 | D17: 489637 | E17: =D17/C17 -> 0.052783442 | F17: MHI / Vahan4 | G17: Registrations
B18: Three Wheeler | C18: 572654 | D18: 300114 | E18: =D18/C18 -> 0.52407562 | F18: MHI / Vahan4 | G18: Registrations
B19: Four Wheeler | C19: 2020459 | D19: 40186 | E19: =D19/C19 -> 0.01988954 | F19: MHI / Vahan4 | G19: Registrations
B20: Goods Vehicles | C20: 490920 | D20: 1512 | E20: =D20/C20 -> 0.0030799316 | F20: MHI / Vahan4 | G20: Registrations
B21: Public Service Vehicle | C21: 47058 | D21: 985 | E21: =D21/C21 -> 0.020931616 | F21: MHI / Vahan4 | G21: Registrations
A22: FY2023-24 | B22: e-2W | D22: 948561 | F22: MHI / Vahan4 | G22: Registrations
A23: FY2024-25 | B23: e-2W | D23: 1149334 | F23: MHI / Vahan4 | G23: Registrations
A24: FY2023-24 | B24: e-3W L5 | D24: 101581 | F24: MHI / Vahan4 | G24: Registrations
A25: FY2024-25 | B25: e-3W L5 | D25: 159235 | F25: MHI / Vahan4 | G25: Registrations
A32: Year | B32: 2W EV Penetration | C32: 3W EV Penetration | D32: 4W EV Penetration
A33: 2020 | B33: =E2 -> 0.0020351442 | C33: =E3 -> 0.22545916 | D33: =E4 -> 0.0013382417
A34: 2021 | B34: =E7 -> 0.011219343 | C34: =E8 -> 0.40460826 | D34: =E9 -> 0.004162168
A35: 2022 | B35: =E12 -> 0.040480774 | C35: =E13 -> 0.51732557 | D35: =E14 -> 0.0099209047
A36: 2023 YTD | B36: =E17 -> 0.052783442 | C36: =E18 -> 0.52407562 | D36: =E19 -> 0.01988954

Sheet Charging_Stations
A1: State | B1: EVs | C1: Operational Public Charging Infrastructure | D1: EVs per Charging Infrastructure | E1: Source | F1: data year | G1: infrastructure for 1000 evs
A2: Chandigarh | B2: 23066 | C2: 14 | D2: =B2/C2 -> 1647.5714 | E2: BEE / EV Yatra | F2: 2025 | G2: =C2*1000/B2 -> 0.60695396
A3: Bihar | B3: 403057 | C3: 388 | D3: =B3/C3 -> 1038.8067 | E3: BEE / EV Yatra | F3: 2025 | G3: =C3*1000/B3 -> 0.962643
A4: Assam | B4: 279245 | C4: 307 | D4: =B4/C4 -> 909.59283 | E4: BEE / EV Yatra | F4: 2025 | G4: =C4*1000/B4 -> 1.099393
A5: Uttar Pradesh | B5: 1404448 | C5: 2099 | D5: =B5/C5 -> 669.10338 | E5: BEE / EV Yatra | F5: 2025 | G5: =C5*1000/B5 -> 1.4945374
A6: Tripura | B6: 34911 | C6: 53 | D6: =B6/C6 -> 658.69811 | E6: BEE / EV Yatra | F6: 2025 | G6: =C6*1000/B6 -> 1.5181461
A7: Chhattisgarh | B7: 158138 | C7: 290 | D7: =B7/C7 -> 545.30345 | E7: BEE / EV Yatra | F7: 2025 | G7: =C7*1000/B7 -> 1.8338413
A8: Uttarakhand | B8: 91843 | C8: 201 | D8: =B8/C8 -> 456.93035 | E8: BEE / EV Yatra | F8: 2025 | G8: =C8*1000/B8 -> 2.1885174
A9: Odisha | B9: 207155 | C9: 534 | D9: =B9/C9 -> 387.93071 | E9: BEE / EV Yatra | F9: 2025 | G9: =C9*1000/B9 -> 2.5777799
A10: Madhya Pradesh | B10: 332223 | C10: 942 | D10: =B10/C10 -> 352.67834 | E10: BEE / EV Yatra | F10: 2025 | G10: =C10*1000/B10 -> 2.8354449
A11: Jharkhand | B11: 97106 | C11: 277 | D11: =B11/C11 -> 350.56318 | E11: BEE / EV Yatra | F11: 2025 | G11: =C11*1000/B11 -> 2.8525529
A12: Puducherry | B12: 14147 | C12: 42 | D12: =B12/C12 -> 336.83333 | E12: BEE / EV Yatra | F12: 2025 | G12: =C12*1000/B12 -> 2.9688273
A13: Rajasthan | B13: 418618 | C13: 1265 | D13: =B13/C13 -> 330.92332 | E13: BEE / EV Yatra | F13: 2025 | G13: =C13*1000/B13 -> 3.0218481
... A36: Sikkim | B36: 49 | C36: 11 | D36: =B36/C36 -> 4.4545455 | E36: BEE / EV Yatra | F36: 2025 | G36: =C36*1000/B36 -> 224.4898
A37: Dadra & Nagar Haveli and Daman & Diu | B37: 1363 | E37: BEE / EV Yatra | F37: 2025 | G37: =C37*1000/B37 -> 0
A40: We can't take that chandigarh as our 1st priority even it has more EVs per station but the total no of EVs are less as per investors perspective its shows a large gap
A42: State | B42: EVs | C42: Operational Public Charging Infrastructure | D42: EVs per Charging Infrastructure | E42: MARKET SIZE CATEGORY | F42: INFRASTRUCTURE PRESSURE
A43: Andaman & Nicobar Islands | B43: 416 | C43: 4 | D43: =B43/C43 -> 104 | E43: =IF(B43>=100000,"High EV Market","Low EV Market") -> Low EV Market | F43: =IF(D43>=500,"High Pressure","Low Pressure") -> Low Pressure
A44: Andhra Pradesh | B44: 180089 | C44: 614 | D44: =B44/C44 -> 293.30456 | E44: =IF(B44>=100000,"High EV Market","Low EV Market") -> High EV Market | F44: =IF(D44>=500,"High Pressure","Low Pressure") -> Low Pressure
A45: Arunachal Pradesh | B45: 317 | C45: 42 | D45: =B45/C45 -> 7.547619 | E45: =IF(B45>=100000,"High EV Market","Low EV Market") -> Low EV Market | F45: =IF(D45>=500,"High Pressure","Low Pressure") -> Low Pressure
A46: Assam | B46: 279245 | C46: 307 | D46: =B46/C46 -> 909.59283 | E46: =IF(B46>=100000,"High EV Market","Low EV Market") -> High EV Market | F46: =IF(D46>=500,"High Pressure","Low Pressure") -> High Pressure
A47: Bihar | B47: 403057 | C47: 388 | D47: =B47/C47 -> 1038.8067 | E47: =IF(B47>=100000,"High EV Market","Low EV Market") -> High EV Market | F47: =IF(D47>=500,"High Pressure","Low Pressure") -> High Pressure
A48: Chandigarh | B48: 23066 | C48: 14 | D48: =B48/C48 -> 1647.5714 | E48: =IF(B48>=100000,"High EV Market","Low EV Market") -> Low EV Market | F48: =IF(D48>=500,"High Pressure","Low Pressure") -> High Pressure
A49: Chhattisgarh | B49: 158138 | C49: 290 | D49: =B49/C49 -> 545.30345 | E49: =IF(B49>=100000,"High EV Market","Low EV Market") -> High EV Market | F49: =IF(D49>=500,"High Pressure","Low Pressure") -> High Pressure
A50: Dadra & Nagar Haveli and Daman & Diu | B50: 1363 | E50: =IF(B50>=100000,"High EV Market","Low EV Market") -> Low EV Market | F50: =IF(D50>=500,"High Pressure","Low Pressure") -> Low Pressure
A51: Delhi | B51: 444202 | C51: 1951 | D51: =B51/C51 -> 227.67914 | E51: =IF(B51>=100000,"High EV Market","Low EV Market") -> High EV Market | F51: =IF(D51>=500,"High Pressure","Low Pressure") -> Low Pressure
A52: Goa | B52: 36009 | C52: 155 | D52: =B52/C52 -> 232.31613 | E52: =IF(B52>=100000,"High EV Market","Low EV Market") -> Low EV Market | F52: =IF(D52>=500,"High Pressure","Low Pressure") -> Low Pressure
A53: Gujarat | B53: 315185 | C53: 1007 | D53: =B53/C53 -> 312.99404 | E53: =IF(B53>=100000,"High EV Market","Low EV Market") -> High EV Market | F53: =IF(D53>=500,"High Pressure","Low Pressure") -> Low Pressure
A54: Haryana | B54: 165718 | C54: 793 | D54: =B54/C54 -> 208.97604 | E54: =IF(B54>=100000,"High EV Market","Low EV Market") -> High EV Market | F54: =IF(D54>=500,"High Pressure","Low Pressure") -> Low Pressure
A55: Himachal Pradesh | B55: 6853 | C55: 112 | D55: =B55/C55 -> 61.1875 | E55: =IF(B55>=100000,"High EV Market","Low EV Market") -> Low EV Market | F55: =IF(D55>=500,"High Pressure","Low Pressure") -> Low Pressure
A56: Jammu & Kashmir | B56: 38150 | C56: 153 | D56: =B56/C56 -> 249.34641 | E56: =IF(B56>=100000,"High EV Market","Low EV Market") -> Low EV Market | F56: =IF(D56>=500,"High Pressure","Low Pressure") -> Low Pressure
A57: Jharkhand | B57: 97106 | C57: 277 | D57: =B57/C57 -> 350.56318 | E57: =IF(B57>=100000,"High EV Market","Low EV Market") -> Low EV Market | F57: =IF(D57>=500,"High Pressure","Low Pressure") -> Low Pressure
A58: Karnataka | B58: 657149 | C58: 5871 | D58: =_xlfn.CEILING.MATH(B58/C58) -> 112 | E58: =IF(B58>=100000,"High EV Market","Low EV Market") -> High EV Market | F58: =IF(D58>=500,"High Pressure","Low Pressure") -> Low Pressure
A59: Kerala | B59: 302347 | C59: 1288 | D59: =B59/C59 -> 234.74146 | E59: =IF(B59>=100000,"High EV Market","Low EV Market") -> High EV Market | F59: =IF(D59>=500,"High Pressure","Low Pressure") -> Low Pressure
A60: Ladakh | B60: 99 | C60: 1 | D60: =B60/C60 -> 99 | E60: =IF(B60>=100000,"High EV Market","Low EV Market") -> Low EV Market | F60: =IF(D60>=500,"High Pressure","Low Pressure") -> Low Pressure
A61: Lakshadweep | B61: 123 | C61: 1 | D61: =B61/C61 -> 123 | E61: =IF(B61>=100000,"High EV Market","Low EV Market") -> Low EV Market | F61: =IF(D61>=500,"High Pressure","Low Pressure") -> Low Pressure
A62: Madhya Pradesh | B62: 332223 | C62: 942 | D62: =B62/C62 -> 352.67834 | E62: =IF(B62>=100000,"High EV Market","Low EV Market") -> High EV Market | F62: =IF(D62>=500,"High Pressure","Low Pressure") -> Low Pressure
A63: Maharashtra | B63: 830189 | C63: 3836 | D63: =B63/C63 -> 216.42049 | E63: =IF(B63>=100000,"High EV Market","Low EV Market") -> High EV Market | F63: =IF(D63>=500,"High Pressure","Low Pressure") -> Low Pressure
A64: Manipur | B64: 2495 | C64: 50 | D64: =B64/C64 -> 49.9 | E64: =IF(B64>=100000,"High EV Market","Low EV Market") -> Low EV Market | F64: =IF(D64>=500,"High Pressure","Low Pressure") -> Low Pressure
A65: Meghalaya | B65: 1719 | C65: 43 | D65: =B65/C65 -> 39.976744 | E65: =IF(B65>=100000,"High EV Market","Low EV Market") -> Low EV Market | F65: =IF(D65>=500,"High Pressure","Low Pressure") -> Low Pressure
...

Sheet Opportunity_model
A1: State | B1: EVs | C1: Current Infrastructure | D1: Current EV/Infrastructure | E1: Benchmark State | F1: Benchmark EV/Infrastructure | G1: Required Infrastructure | H1: Infrastructure Gap | I1: Benchmark State | J1: Benchmark EV/Infrastructure | K1: Required Infrastructure | L1: Infrastructure Gap
A2: Uttar Pradesh | B2: =Charging_Stations!B76 -> 1404448 | C2: =Charging_Stations!C76 -> 2099 | D2: =B2/C2 -> 669.10338 | E2: Maharashtra | F2: =Charging_Stations!D63 -> 216.42049 | G2: =B2/F2 -> 6489.441 | H2: =G2-C2 -> 4390.441 | I2: karnataka | J2: =Charging_Stations!D58 -> 112 | K2: =B2/J2 -> 12539.714 | L2: =K2-D2 -> 11870.611
A3: Bihar | B3: =Charging_Stations!B47 -> 403057 | C3: =Charging_Stations!C47 -> 388 | D3: =B3/C3 -> 1038.8067 | E3: Maharashtra | F3: =Charging_Stations!D63 -> 216.42049 | G3: =B3/F3 -> 1862.3791 | H3: =G3-C3 -> 1474.3791 | I3: karnataka | J3: =Charging_Stations!D58 -> 112 | K3: =B3/J3 -> 3598.7232 | L3: =K3-D3 -> 2559.9165
A4: Assam | B4: =Charging_Stations!B46 -> 279245 | C4: =Charging_Stations!C46 -> 307 | D4: =B4/C4 -> 909.59283 | E4: Maharashtra | F4: =Charging_Stations!D63 -> 216.42049 | G4: =B4/F4 -> 1290.2891 | H4: =G4-C4 -> 983.2891 | I4: karnataka | J4: =Charging_Stations!D58 -> 112 | K4: =B4/J4 -> 2493.2589 | L4: =K4-D4 -> 1583.6661
A7: Guesstimate 1
A9: How many additional charging stations could be required?
A11: Guesstimate 2
A13: What would it cost to build them?
A15: Guesstimate 3
A17: How much annual charging revenue could they generate?
A19: Guesstimate 4
A21: What utilization rate is required to break even?
A23: Guesstimate 5
A25: What is the potential market size for charging infrastructure?

Sheet capex_model
A1: State | B1: Scenario | C1: Gap | D1: Cost base | E1: Cost high | F1: Estimated CAPEX
A2: Uttar Pradesh | B2: Maharashtra | C2: 4390 | D2: ₹7L | E2: ₹20L | F2: ₹307.3 Cr-875 Cr
A3: Uttar Pradesh | B3: Karnataka | C3: 11871 | D3: ₹7L | E3: ₹20L | F3: ₹831.5 Cr-2369.7 Cr
A4: Bihar | B4: Maharashtra | C4: 1474 | D4: ₹7L | E4: ₹20L | F4: ₹103.2 Cr-285Cr
A5: Bihar | B5: Karnataka | C5: 2560 | D5: ₹7L | E5: ₹20L | F5: ₹179.3 Cr-511Cr
A6: Assam | B6: Maharashtra | C6: 983 | D6: ₹7L | E6: ₹20L | F6: ₹68.8 Cr-196.6Cr
A7: Assam | B7: Karnataka | C7: 1584 | D7: ₹7L | E7: ₹20L | F7: ₹111.0 Cr-316.35 Cr

Sheet revenue_model
A1: assuming 8 utilizations per day and 10kWH each time
A6: State | B6: Scenario | C6: Infrastructure Gap | D6: Utilization / Day | E6: Energy Sold / Session (kWh) | F6: Revenue / kWh | G6: Annual Revenue | H6: Revenue (₹ Cr) | I6: Estimated CAPEX | J6: ROI
A7: Uttar Pradesh | B7: Maharashtra Benchmark | C7: 4390 | D7: 8 | E7: 10 | F7: 15 | G7: =C7*D7*E7*F7*365 -> 1922820000 | H7: =G7/10000000 -> 192.282 | I7: ₹307.3 Cr-875 Cr | J7: 2 TO 3 YEARS for base model
A8: Uttar Pradesh | B8: Karnataka Benchmark | C8: 11871 | D8: 8 | E8: 10 | F8: 15 | G8: =C8*D8*E8*F8*365 -> 5199498000 | H8: =G8/10000000 -> 519.9498 | I8: ₹831.5 Cr-2369.7 Cr | J8: 3 TO 3 YEARS for base model
A9: Bihar | B9: Maharashtra Benchmark | C9: 1474 | D9: 8 | E9: 10 | F9: 15 | G9: =C9*D9*E9*F9*365 -> 645612000 | H9: =G9/10000000 -> 64.5612 | I9: ₹103.2 Cr-285Cr | J9: 4 TO 3 YEARS for base model
A10: Bihar | B10: Karnataka Benchmark | C10: 2560 | D10: 8 | E10: 10 | F10: 15 | G10: =C10*D10*E10*F10*365 -> 1121280000 | H10: =G10/10000000 -> 112.128 | I10: ₹179.3 Cr-511Cr | J10: 5 TO 3 YEARS for base model
A11: Assam | B11: Maharashtra Benchmark | C11: 983 | D11: 8 | E11: 10 | F11: 15 | G11: =C11*D11*E11*F11*365 -> 430554000 | H11: =G11/10000000 -> 43.0554 | I11: ₹68.8 Cr-196.6Cr | J11: 6 TO 3 YEARS for base model
A12: Assam | B12: Karnataka Benchmark | C12: 1584 | D12: 8 | E12: 10 | F12: 15 | G12: =C12*D12*E12*F12*365 -> 693792000 | H12: =G12/10000000 -> 69.3792 | I12: ₹111.0 Cr-316.35 Cr | J12: 7 TO 3 YEARS for base model
A14: IF utilizations increase from 8+ then roi decreases

Sheet Clean_Data

Sheet Historical_Analysis
A1: Year | B1: EV Registrations | C1: YoY Growth
A2: 2020 | B2: =EV_Registrations!B59 -> 124681
A3: 2021 | B3: =EV_Registrations!C59 -> 331635 | C3: =((B3-B2)/B2)*100 -> 165.9868
A4: 2022 | B4: =EV_Registrations!D59 -> 1025118 | C4: =((B4-B3)/B3)*100 -> 209.11032
A5: 2023ytd | B5: =EV_Registrations!E59 -> 1395701 | C5: =((B5-B4)/B4)*100 -> 36.150277
A7: top 10 states with more ev sales
A8: State | B8: 2020 | C8: 2021 | D8: 2022 | E8: 2023_YTD | F8: Grand_Total | G8: market share
A9: Uttar Pradesh | B9: 31268 | C9: 66705 | D9: 162862 | E9: 249223 | F9: =SUM(B9:E9) -> 510058 | G9: =(Historical_Analysis!F9/EV_Registrations!F59)*100 -> 17.727983
A10: Maharashtra | B10: 7134 | C10: 29914 | D10: 136051 | E10: 178488 | F10: =SUM(B10:E10) -> 351587 | G10: =(Historical_Analysis!F10/EV_Registrations!F59)*100 -> 12.220038
A11: Karnataka | B11: 9707 | C11: 33307 | D11: 95900 | E11: 141057 | F11: =SUM(B11:E11) -> 279971 | G11: =(Historical_Analysis!F11/EV_Registrations!F59)*100 -> 9.7308955
A12: Rajasthan | B12: 5604 | C12: 23464 | D12: 78238 | E12: 86376 | F12: =SUM(B12:E12) -> 193682 | G12: =(Historical_Analysis!F12/EV_Registrations!F59)*100 -> 6.7317661
A13: Tamil Nadu | B13: 5697 | C13: 30030 | D13: 66953 | E13: 84252 | F13: =SUM(B13:E13) -> 186932 | G13: =(Historical_Analysis!F13/EV_Registrations!F59)*100 -> 6.4971578
A14: Bihar | B14: 12447 | C14: 23082 | D14: 55751 | E14: 79469 | F14: =SUM(B14:E14) -> 170749 | G14: =(Historical_Analysis!F14/EV_Registrations!F59)*100 -> 5.9346885
A15: Delhi | B15: 12377 | C15: 25816 | D15: 62256 | E15: 64382 | F15: =SUM(B15:E15) -> 164831 | G15: =(Historical_Analysis!F15/EV_Registrations!F59)*100 -> 5.7289978
A16: Gujarat | B16: 1120 | C16: 9765 | D16: 68998 | E16: 83965 | F16: =SUM(B16:E16) -> 163848 | G16: =(Historical_Analysis!F16/EV_Registrations!F59)*100 -> 5.6948318
A17: Assam | B17: 8357 | C17: 15634 | D17: 40719 | E17: 56448 | F17: =SUM(B17:E17) -> 121158 | G17: =(Historical_Analysis!F17/EV_Registrations!F59)*100 -> 4.2110641
A18: Kerala | B18: 1362 | C18: 8743 | D18: 39622 | E18: 69624 | F18: =SUM(B18:E18) -> 119351 | G18: =(Historical_Analysis!F18/EV_Registrations!F59)*100 -> 4.1482586
A21: Top 5 combined:≈ 52.9%
A22: So roughly half of the EV registrations in this dataset are concentrated in just five states.
A23: That's a very useful finding for our eventual charging-infrastructure project.
